
Error: Python: Traceback (most recent call last):
  File "\Text", line 23, in <module>
AttributeError: 'list' object has no attribute 'values'
